Workbook

Sheet Лист1
A2: cs 2 | C2: Время | D2: # | E2: Команда А | F2: Команда В
C3: 10:30 - 11:30 | D3: Матч 1 | E3: =VLOOKUP(G3,[1]Участники!$C$13:$D$38,2,0) -> LukTechPrime | F3: =VLOOKUP(H3,[1]Участники!$C$13:$D$38,2,0) -> sqwoz_dust | G3: Команда 1 | H3: Команда 2
C4: 10:30 - 11:30 | D4: Матч 2 | E4: =VLOOKUP(G4,[1]Участники!$C$13:$D$38,2,0) -> CSPerm | F4: =VLOOKUP(H4,[1]Участники!$C$13:$D$38,2,0) -> Victory | G4: Команда 3 | H4: Команда 4
C5: 11:30 - 12:30 | D5: Матч 3 | E5: =VLOOKUP(G5,[1]Участники!$C$13:$D$38,2,0) -> LukTechPrime | F5: =VLOOKUP(H5,[1]Участники!$C$13:$D$38,2,0) -> CSPerm | G5: Команда 1 | H5: Команда 3
C6: 11:30 - 12:30 | D6: Матч 4 | E6: =VLOOKUP(G6,[1]Участники!$C$13:$D$38,2,0) -> sqwoz_dust | F6: =VLOOKUP(H6,[1]Участники!$C$13:$D$38,2,0) -> Широлапики | G6: Команда 2 | H6: Команда 5
C7: 13:30 - 14:30 | D7: Матч 5 | E7: =VLOOKUP(G7,[1]Участники!$C$13:$D$38,2,0) -> LukTechPrime | F7: =VLOOKUP(H7,[1]Участники!$C$13:$D$38,2,0) -> Victory | G7: Команда 1 | H7: Команда 4
C8: 13:30 - 14:30 | D8: Матч 6 | E8: =VLOOKUP(G8,[1]Участники!$C$13:$D$38,2,0) -> CSPerm | F8: =VLOOKUP(H8,[1]Участники!$C$13:$D$38,2,0) -> Широлапики | G8: Команда 3 | H8: Команда 5
C9: 14:30 - 15:30 | D9: Матч 7 | E9: =VLOOKUP(G9,[1]Участники!$C$13:$D$38,2,0) -> LukTechPrime | F9: =VLOOKUP(H9,[1]Участники!$C$13:$D$38,2,0) -> Широлапики | G9: Команда 1 | H9: Команда 5
C10: 14:30 - 15:30 | D10: Матч 8 | E10: =VLOOKUP(G10,[1]Участники!$C$13:$D$38,2,0) -> sqwoz_dust | F10: =VLOOKUP(H10,[1]Участники!$C$13:$D$38,2,0) -> Victory | G10: Команда 2 | H10: Команда 4
C11: 15:30 - 16:30 | D11: Матч 9 | E11: =VLOOKUP(G11,[1]Участники!$C$13:$D$38,2,0) -> sqwoz_dust | F11: =VLOOKUP(H11,[1]Участники!$C$13:$D$38,2,0) -> CSPerm | G11: Команда 2 | H11: Команда 3
C12: 15:30 - 16:30 | D12: Матч 10 | E12: =VLOOKUP(G12,[1]Участники!$C$13:$D$38,2,0) -> Victory | F12: =VLOOKUP(H12,[1]Участники!$C$13:$D$38,2,0) -> Широлапики | G12: Команда 4 | H12: Команда 5
A14: Mortal Kombat | C14: Приставка | D14: Время | E14: # | F14: Команда А | G14: Команда В
C15: 1 | D15: 11:30-11:35 | E15: Матч 1 | F15: =VLOOKUP(H15,[1]Участники!$C$49:$D$562,2,0) -> Васина В. | G15: =VLOOKUP(I15,[1]Участники!$C$49:$D$562,2,0) -> Чепендюк Е. | H15: 1 | I15: 8
D16: 11:35-11:40 | E16: Матч 2 | F16: =VLOOKUP(H16,[1]Участники!$C$49:$D$562,2,0) -> Васина В. | G16: =VLOOKUP(I16,[1]Участники!$C$49:$D$562,2,0) -> Хасянов М. | H16: 1 | I16: 7
D17: 11:45-11:50 | E17: Матч 3 | F17: =VLOOKUP(H17,[1]Участники!$C$49:$D$562,2,0) -> Васина В. | G17: =VLOOKUP(I17,[1]Участники!$C$49:$D$562,2,0) -> Изранцева В. | H17: 1 | I17: 2
D18: 11:50-11:55 | E18: Матч 4 | F18: =VLOOKUP(H18,[1]Участники!$C$49:$D$562,2,0) -> Изранцева В. | G18: =VLOOKUP(I18,[1]Участники!$C$49:$D$562,2,0) -> Исаев Д. | H18: 2 | I18: 5 | K18: 1 | L18: 3 | M18: 2
D19: 11:55-12:00 | E19: Матч 5 | F19: =VLOOKUP(H19,[1]Участники!$C$49:$D$562,2,0) -> Изранцева В. | G19: =VLOOKUP(I19,[1]Участники!$C$49:$D$562,2,0) -> Неталиев А. | H19: 2 | I19: 6 | K19: 2 | L19: 3 | M19: 2
D20: 12:05-12:10 | E20: Матч 6 | F20: =VLOOKUP(H20,[1]Участники!$C$49:$D$562,2,0) -> Гуров И. | G20: =VLOOKUP(I20,[1]Участники!$C$49:$D$562,2,0) -> Неталиев А. | H20: 4 | I20: 6 | K20: 3 | L20: 3 | M20: 2
D21: 12:10-12:15 | E21: Матч 7 | F21: =VLOOKUP(H21,[1]Участники!$C$49:$D$562,2,0) -> Гуров И. | G21: =VLOOKUP(I21,[1]Участники!$C$49:$D$562,2,0) -> Васина В. | H21: 4 | I21: 1 | K21: 4 | L21: 3 | M21: 2
C22: 2 | D22: 11:30-11:35 | E22: Матч 8 | F22: =VLOOKUP(H22,[1]Участники!$C$49:$D$562,2,0) -> Исаев Д. | G22: =VLOOKUP(I22,[1]Участники!$C$49:$D$562,2,0) -> Гуров И. | H22: 5 | I22: 4 | K22: 5 | L22: 3
D23: 11:35-11:40 | E23: Матч 9 | F23: =VLOOKUP(H23,[1]Участники!$C$49:$D$562,2,0) -> Изранцева В. | G23: =VLOOKUP(I23,[1]Участники!$C$49:$D$562,2,0) -> Гуров И. | H23: 2 | I23: 4 | K23: 6 | L23: 3 | M23: 2 | W23: =SUM(#REF!) -> #REF!
D24: 11:45-11:50 | E24: Матч 10 | F24: =VLOOKUP(H24,[1]Участники!$C$49:$D$562,2,0) -> Шайнога Б. | G24: =VLOOKUP(I24,[1]Участники!$C$49:$D$562,2,0) -> Гуров И. | H24: 3 | I24: 4 | K24: 7 | L24: 3 | W24: =SUM(#REF!) -> #REF!
D25: 11:50-11:55 | E25: Матч 11 | F25: =VLOOKUP(H25,[1]Участники!$C$49:$D$562,2,0) -> Васина В. | G25: =VLOOKUP(I25,[1]Участники!$C$49:$D$562,2,0) -> Неталиев А. | H25: 1 | I25: 6 | K25: 8 | L25: 3 | W25: =SUM(#REF!) -> #REF!
D26: 11:55-12:00 | E26: Матч 12 | F26: =VLOOKUP(H26,[1]Участники!$C$49:$D$562,2,0) -> Васина В. | G26: =VLOOKUP(I26,[1]Участники!$C$49:$D$562,2,0) -> Шайнога Б. | H26: 1 | I26: 3 | W26: =SUM(#REF!) -> #REF!
D27: 12:05-12:10 | E27: Матч 13 | F27: =VLOOKUP(H27,[1]Участники!$C$49:$D$562,2,0) -> Хасянов М. | G27: =VLOOKUP(I27,[1]Участники!$C$49:$D$562,2,0) -> Шайнога Б. | H27: 7 | I27: 3 | W27: =SUM(#REF!) -> #REF!
D28: 12:10-12:15 | E28: Матч 14 | F28: =VLOOKUP(H28,[1]Участники!$C$49:$D$562,2,0) -> Неталиев А. | G28: =VLOOKUP(I28,[1]Участники!$C$49:$D$562,2,0) -> Шайнога Б. | H28: 6 | I28: 3 | W28: =SUM(#REF!) -> #REF!
C29: 3 | D29: 11:30-11:35 | E29: Матч 15 | F29: =VLOOKUP(H29,[1]Участники!$C$49:$D$562,2,0) -> Шайнога Б. | G29: =VLOOKUP(I29,[1]Участники!$C$49:$D$562,2,0) -> Изранцева В. | H29: 3 | I29: 2 | K29: 1 | L29: 8 | N29: 5 | O29: 4 | Q29: 3 | R29: 2 | T29: 7 | U29: 6 | W29: =SUM(#REF!) -> #REF!
D30: 11:35-11:40 | E30: Матч 16 | F30: =VLOOKUP(H30,[1]Участники!$C$49:$D$562,2,0) -> Шайнога Б. | G30: =VLOOKUP(I30,[1]Участники!$C$49:$D$562,2,0) -> Исаев Д. | H30: 3 | I30: 5 | K30: 1 | L30: 7 | N30: 2 | O30: 4 | Q30: 3 | R30: 5 | T30: 8 | U30: 6
D31: 11:45-11:50 | E31: Матч 17 | F31: =VLOOKUP(H31,[1]Участники!$C$49:$D$562,2,0) -> Хасянов М. | G31: =VLOOKUP(I31,[1]Участники!$C$49:$D$562,2,0) -> Чепендюк Е. | H31: 7 | I31: 8 | K31: 1 | L31: 2 | N31: 3 | O31: 4 | Q31: 7 | R31: 8 | T31: 5 | U31: 6
D32: 11:50-11:55 | E32: Матч 18 | F32: =VLOOKUP(H32,[1]Участники!$C$49:$D$562,2,0) -> Хасянов М. | G32: =VLOOKUP(I32,[1]Участники!$C$49:$D$562,2,0) -> Гуров И. | H32: 7 | I32: 4 | K32: 2 | L32: 5 | N32: 1 | O32: 6 | Q32: 7 | R32: 4 | T32: 8 | U32: 3
D33: 11:55-12:00 | E33: Матч 19 | F33: =VLOOKUP(H33,[1]Участники!$C$49:$D$562,2,0) -> Хасянов М. | G33: =VLOOKUP(I33,[1]Участники!$C$49:$D$562,2,0) -> Исаев Д. | H33: 7 | I33: 5 | K33: 2 | L33: 6 | N33: 1 | O33: 3 | Q33: 7 | R33: 5 | T33: 8 | U33: 4
D34: 12:05-12:10 | E34: Матч 20 | F34: =VLOOKUP(H34,[1]Участники!$C$49:$D$562,2,0) -> Васина В. | G34: =VLOOKUP(I34,[1]Участники!$C$49:$D$562,2,0) -> Исаев Д. | H34: 1 | I34: 5 | K34: 4 | L34: 6 | N34: 7 | O34: 3 | Q34: 1 | R34: 5 | T34: 8 | U34: 2
D35: 12:10-12:15 | E35: Матч 21 | F35: =VLOOKUP(H35,[1]Участники!$C$49:$D$562,2,0) -> Чепендюк Е. | G35: =VLOOKUP(I35,[1]Участники!$C$49:$D$562,2,0) -> Исаев Д. | H35: 8 | I35: 5 | K35: 4 | L35: 1 | N35: 6 | O35: 3 | Q35: 8 | R35: 5 | T35: 2 | U35: 7
C36: 4 | D36: 11:30-11:35 | E36: Матч 22 | F36: =VLOOKUP(H36,[1]Участники!$C$49:$D$562,2,0) -> Хасянов М. | G36: =VLOOKUP(I36,[1]Участники!$C$49:$D$562,2,0) -> Неталиев А. | H36: 7 | I36: 6
D37: 11:35-11:40 | E37: Матч 23 | F37: =VLOOKUP(H37,[1]Участники!$C$49:$D$562,2,0) -> Чепендюк Е. | G37: =VLOOKUP(I37,[1]Участники!$C$49:$D$562,2,0) -> Неталиев А. | H37: 8 | I37: 6
D38: 11:45-11:50 | E38: Матч 24 | F38: =VLOOKUP(H38,[1]Участники!$C$49:$D$562,2,0) -> Исаев Д. | G38: =VLOOKUP(I38,[1]Участники!$C$49:$D$562,2,0) -> Неталиев А. | H38: 5 | I38: 6
D39: 11:50-11:55 | E39: Матч 25 | F39: =VLOOKUP(H39,[1]Участники!$C$49:$D$562,2,0) -> Чепендюк Е. | G39: =VLOOKUP(I39,[1]Участники!$C$49:$D$562,2,0) -> Шайнога Б. | H39: 8 | I39: 3
D40: 11:55-12:00 | E40: Матч 26 | F40: =VLOOKUP(H40,[1]Участники!$C$49:$D$562,2,0) -> Чепендюк Е. | G40: =VLOOKUP(I40,[1]Участники!$C$49:$D$562,2,0) -> Гуров И. | H40: 8 | I40: 4
D41: 12:05-12:10 | E41: Матч 27 | F41: =VLOOKUP(H41,[1]Участники!$C$49:$D$562,2,0) -> Чепендюк Е. | G41: =VLOOKUP(I41,[1]Участники!$C$49:$D$562,2,0) -> Изранцева В. | H41: 8 | I41: 2 | K41: 3 | L41: 4 | N41: 1 | O41: 6 | Q41: 2 | R41: 5
D42: 12:10-12:15 | E42: Матч 28 | F42: =VLOOKUP(H42,[1]Участники!$C$49:$D$562,2,0) -> Изранцева В. | G42: =VLOOKUP(I42,[1]Участники!$C$49:$D$562,2,0) -> Хасянов М. | H42: 2 | I42: 7 | K42: 3 | L42: 6 | N42: 1 | O42: 5 | Q42: 2 | R42: 4
...
